Traceback (most recent call last):
  File "/Users/adzcai/micromamba/envs/rlbook/lib/python3.11/site-packages/jupyter_cache/executors/utils.py", line 58, in single_nb_execution
    executenb(
  File "/Users/adzcai/micromamba/envs/rlbook/lib/python3.11/site-packages/nbclient/client.py", line 1305, in execute
    return NotebookClient(nb=nb, resources=resources, km=km, **kwargs).execute()
           ^^^^^^^^^^^^^^^^^^^^^^^^^^^^^^^^^^^^^^^^^^^^^^^^^^^^^^^^^^^^^^^^^^^^^
  File "/Users/adzcai/micromamba/envs/rlbook/lib/python3.11/site-packages/jupyter_core/utils/__init__.py", line 165, in wrapped
    return loop.run_until_complete(inner)
           ^^^^^^^^^^^^^^^^^^^^^^^^^^^^^^
  File "/Users/adzcai/micromamba/envs/rlbook/lib/python3.11/asyncio/base_events.py", line 654, in run_until_complete
    return future.result()
           ^^^^^^^^^^^^^^^
  File "/Users/adzcai/micromamba/envs/rlbook/lib/python3.11/site-packages/nbclient/client.py", line 705, in async_execute
    await self.async_execute_cell(
  File "/Users/adzcai/micromamba/envs/rlbook/lib/python3.11/site-packages/nbclient/client.py", line 1058, in async_execute_cell
    await self._check_raise_for_error(cell, cell_index, exec_reply)
  File "/Users/adzcai/micromamba/envs/rlbook/lib/python3.11/site-packages/nbclient/client.py", line 914, in _check_raise_for_error
    raise CellExecutionError.from_cell_and_msg(cell, exec_reply_content)
nbclient.exceptions.CellExecutionError: An error occurred while executing the following cell:
------------------
class LinUCBPseudocode(Agent):
    def __init__(
        self, K: int, T: int, D: int, lam: float, get_c: Callable[[int], float]
    ):
        super().__init__(K, T)
        self.lam = lam
        self.get_c = get_c
        self.contexts = [None for _ in range(K)]
        self.A = np.repeat(lam * np.eye(D)[...], K)
        self.targets = np.zeros(K, D)
        self.w = np.zeros(K, D)

    def choose_arm(self, context: Float[Array, " D"]):
        c = self.get_c(self.count)
        scores = self.w @ context + c * np.sqrt(
            context.T @ np.linalg.solve(self.A, context)
        )
        return random_argmax(scores)

    def update_history(self, context: Float[Array, " D"], arm: int, reward: int):
        self.A[arm] += np.outer(context, context)
        self.targets[arm] += context * reward
        self.w[arm] = np.linalg.solve(self.A[arm], self.targets[arm])
------------------


[0;31m---------------------------------------------------------------------------[0m
[0;31mNameError[0m                                 Traceback (most recent call last)
Cell [0;32mIn[1], line 1[0m
[0;32m----> 1[0m [38;5;28;01mclass[39;00m [38;5;21;01mLinUCBPseudocode[39;00m([43mAgent[49m):
[1;32m      2[0m     [38;5;28;01mdef[39;00m [38;5;21m__init__[39m(
[1;32m      3[0m         [38;5;28mself[39m, K: [38;5;28mint[39m, T: [38;5;28mint[39m, D: [38;5;28mint[39m, lam: [38;5;28mfloat[39m, get_c: Callable[[[38;5;28mint[39m], [38;5;28mfloat[39m]
[1;32m      4[0m     ):
[1;32m      5[0m         [38;5;28msuper[39m()[38;5;241m.[39m[38;5;21m__init__[39m(K, T)

[0;31mNameError[0m: name 'Agent' is not defined

