Traceback (most recent call last):
  File "/Users/alexandercai/micromamba/envs/rlbook/lib/python3.11/site-packages/jupyter_cache/executors/utils.py", line 58, in single_nb_execution
    executenb(
  File "/Users/alexandercai/micromamba/envs/rlbook/lib/python3.11/site-packages/nbclient/client.py", line 1314, in execute
    return NotebookClient(nb=nb, resources=resources, km=km, **kwargs).execute()
           ^^^^^^^^^^^^^^^^^^^^^^^^^^^^^^^^^^^^^^^^^^^^^^^^^^^^^^^^^^^^^^^^^^^^^
  File "/Users/alexandercai/micromamba/envs/rlbook/lib/python3.11/site-packages/jupyter_core/utils/__init__.py", line 165, in wrapped
    return loop.run_until_complete(inner)
           ^^^^^^^^^^^^^^^^^^^^^^^^^^^^^^
  File "/Users/alexandercai/micromamba/envs/rlbook/lib/python3.11/asyncio/base_events.py", line 654, in run_until_complete
    return future.result()
           ^^^^^^^^^^^^^^^
  File "/Users/alexandercai/micromamba/envs/rlbook/lib/python3.11/site-packages/nbclient/client.py", line 709, in async_execute
    await self.async_execute_cell(
  File "/Users/alexandercai/micromamba/envs/rlbook/lib/python3.11/site-packages/nbclient/client.py", line 1062, in async_execute_cell
    await self._check_raise_for_error(cell, cell_index, exec_reply)
  File "/Users/alexandercai/micromamba/envs/rlbook/lib/python3.11/site-packages/nbclient/client.py", line 918, in _check_raise_for_error
    raise CellExecutionError.from_cell_and_msg(cell, exec_reply_content)
nbclient.exceptions.CellExecutionError: An error occurred while executing the following cell:
------------------
def dagger(
    env: MAB,
    Ï€_init: Policy,
    Ï€_expert: Policy,
    n_dagger_iterations: int,
    n_trajectories_per_iteration: int
):
    Ï€ = Ï€_init
    dataset = set()

    for _ in range(n_dagger_iterations):
        for __ in range(n_trajectories_per_iteration):
            Ï„ = collect_trajectory(Ï€, env)
            for step in range(env.H):
                obs = Ï„.state[step]
                Ï„.action[step] = Ï€_expert(obs)
            dataset.add(Ï„)
        
        Ï€ = fit(dataset)
    
    return Ï€
------------------


[0;31m---------------------------------------------------------------------------[0m
[0;31mNameError[0m                                 Traceback (most recent call last)
Cell [0;32mIn[1], line 2[0m
[1;32m      1[0m [38;5;28;01mdef[39;00m [38;5;21mdagger[39m(
[0;32m----> 2[0m     env: [43mMAB[49m,
[1;32m      3[0m     Ï€_init: Policy,
[1;32m      4[0m     Ï€_expert: Policy,
[1;32m      5[0m     n_dagger_iterations: [38;5;28mint[39m,
[1;32m      6[0m     n_trajectories_per_iteration: [38;5;28mint[39m
[1;32m      7[0m ):
[1;32m      8[0m     Ï€ [38;5;241m=[39m Ï€_init
[1;32m      9[0m     dataset [38;5;241m=[39m [38;5;28mset[39m()

[0;31mNameError[0m: name 'MAB' is not defined

